Workbook

Sheet Summary
A1: GEB Platform Upgrade — Migration Effort Estimation
A2: Wipro Consulting | UOB Singapore | Confidential | April 2026
A4: # | B4: Layer / Component | C4: Mandays (Dev) | D4: PPT Reference | E4: Complexity | F4: Volume | G4: Notes
A5: 1 | B5: Layer 1 — Core Platform Migration
A6: 1.1 | B6: Java 8 → Java 17 + javax→jakarta | C6: ='Layer 1'!E14 -> 0 | D6: Slide 2 — Stack Overview | E6: Medium | F6: High | G6: Namespace changes across codebase
A7: 1.2 | B7: JBoss EAP 7.3 → EAP 8 | C7: ='Layer 1'!E19 -> 0 | D7: Slide 2 — Stack Overview | E7: Low | F7: Low | G7: Runtime + deployment config
A8: 1.3 | B8: Turbine 2.3.3 → Turbine 7.0 | C8: ='Layer 1'!E30 -> 0 | D8: Slide 3 — Turbine | E8: High | F8: High | G8: Framework redesign — RunData, pipeline, services
A9: 1.4 | B9: Torque 3.1.1 → Torque 5.1+ | C9: ='Layer 1'!E39 -> 0 | D9: Slide 4 — Torque ORM | E9: Medium | F9: Low | G9: Criteria API, Village, Peer regeneration
A10: 1.5 | B10: Spring 4.2.9 → Spring 6.x | C10: ='Layer 1'!E49 -> 0 | D10: Slide 5 — Spring & WSService | E10: High | F10: Medium | G10: ArgumentResolver, Security, Springfox
A11: 1.6 | B11: View Layer (Jetspeed/Castor/XSL) | C11: ='Layer 1'!E57 -> 0 | D11: Slide 6 — View Layer | E11: Medium | F11: Low | G11: Castor→dom4j, base class updates
A12: 1.7 | B12: JAR Dependencies | C12: ='Layer 1'!E66 -> 0 | D12: Slide 2 — Stack Overview | E12: Medium | F12: Medium | G12: Classification + upgrade/replace
A13: 1.8 | B13: Build System (Ant → Maven) | C13: ='Layer 1'!E71 -> 0 | D13: Slide 2 — Stack Overview | E13: Medium | F13: One-time | G13: Phase 0 prerequisite
B15: LAYER 1 TOTAL | C15: =SUM(C6:C13) -> 0
A17: 2 | B17: Layer 2 — Module-Level Migration
A18: 2.x | B18: (To be detailed — see Layer 2 sheet) | C18: ='Layer 2'!E100 -> 0 | D18: Module-specific | G18: Functional validation per business module
B20: LAYER 2 TOTAL | C20: =C19 -> 0
A22: 3 | B22: Layer 3 — Integration & Build
A23: 3.x | B23: (To be detailed — see Layer 3 sheet) | C23: ='Layer 3'!E20 -> 0 | G23: Cross-module, multi-country, deployment
B25: LAYER 3 TOTAL | C25: =C24 -> 0
B27: GRAND TOTAL (Dev Mandays) | C27: =C15+C21+C26 -> 0 | G27: Scope: until Build. Testing/buffer by senior management.

Sheet Layer 1
A1: Layer 1 — Core Platform Migration (Development Mandays)
A2: Maps to PPT: Stack Migration — Component Risk Map and subsequent detail slides
A4: S.No | B4: Component | C4: Task | D4: Description | E4: Mandays (Dev) | F4: Owner | G4: Assumptions / Notes
A5: 1. Java 8 → Java 17 + javax.* → jakarta.* Namespace Migration [PPT: Slide 2]
A6: 1 | B6: Java / Jakarta EE | C6: javax.servlet → jakarta.servlet migration | D6: Update all javax.servlet imports to jakarta.servlet across GEB source code. Includes HttpServletRequest, HttpServletResponse, ServletContext, Filter interfaces. | G6: Scope depends on file count. Can be partially automated via OpenRewrite after Maven conversion.
A7: 2 | B7: Java / Jakarta EE | C7: javax.validation → jakarta.validation | D7: Update Bean Validation API imports. Includes @Valid, @NotNull, custom constraint validators. | G7: Lower volume than servlet — used primarily in Spring controllers.
A8: 3 | B8: Java / Jakarta EE | C8: javax.annotation → jakarta.annotation | D8: Update @PostConstruct, @Resource annotations. NOTE: javax.annotation.Generated stays as-is (Java SE). | G8: Careful: not all javax.annotation classes migrate — only EE-specific ones.
A9: 4 | B9: Java / Jakarta EE | C9: Java 8 → 17 API compatibility fixes | D9: Fix any Java 8 specific API usage deprecated/removed in Java 17. Includes removed packages, reflection access restrictions. | G9: Minimal expected — most Java 8 code runs on 17. Strong encapsulation may affect reflection-heavy code.
A10: 5 | B10: Java / Jakarta EE | C10: JDK 17 compilation and runtime testing | D10: Compile full GEB source against JDK 17, resolve compilation errors, verify runtime behaviour. | G10: Iterative process — compile, fix, recompile.
A11: Java + Jakarta Namespace Subtotal | E11: =SUM(E6:E10) -> 0
A12: 2. JBoss EAP 7.3 → EAP 8 (Server Runtime) [PPT: Slide 2]
A13: 10 | B13: JBoss EAP | C13: EAP 8 server configuration | D13: Configure EAP 8 standalone/domain mode. Update datasource, connection pool, JMS, logging, security subsystem configs. | G13: Reference existing EAP 7.3 standalone.xml.
A14: 11 | B14: JBoss EAP | C14: Deployment descriptor updates | D14: Update web.xml, jboss-web.xml, jboss-deployment-structure.xml for EAP 8 namespace and module structure. | G14: Finite set of files.
A15: 12 | B15: JBoss EAP | C15: EAP 8 deployment and startup validation | D15: Deploy GEB WAR/EAR on EAP 8, resolve classloading issues, validate startup, verify JNDI and datasource connectivity. | G15: Iterative — deploy, debug, fix, redeploy.
A16: JBoss EAP Subtotal | E16: =SUM(E13:E15) -> 0
A17: 3. Turbine 2.3.3 → Turbine 7.0 (Framework) [PPT: Slide 3]
A18: 20 | B18: Turbine | C18: RunData → PipelineData migration | D18: Add PipelineData parameter and RunData cast to every Action, Layout, and Portlet class. Business logic after cast unchanged. | G18: High volume, low complexity per file. One cast line per class.
A19: 21 | B19: Turbine | C19: Abstract classes → Interfaces adaptation | D19: Action and Layout changed from abstract classes to interfaces. Inherited helper methods removed — must be sourced independently. | G19: 200+ classes need method signature changes.
A20: 22 | B20: Turbine | C20: YAAFI container setup + 3 XML configs | D20: Create containerConfiguration.xml, roleConfiguration.xml, componentConfiguration.xml for Fulcrum/YAAFI. | G20: One-time config creation. Reference Turbine 7 documentation.
A21: 23 | B21: Turbine | C21: pipeline.xml creation + GTPExecuteValve | D21: Create pipeline.xml defining request flow as valves. Write custom GTPExecuteValve (GEB skips Turbine Page mechanism). | G21: One config file + one custom valve class.
A22: 24 | B22: Turbine | C22: Service re-registration (17 banking + 10 platform) | D22: Re-register 27 GEB services in new dual-container model. Config path changes — service code largely unchanged. | G22: 33 services total. 6 core Turbine services auto-handled.
A23: 25 | B23: Turbine | C23: GTPRunDataService adaptation | D23: Adapt custom RunDataService for Turbine 7 container lifecycle. Pool assembly of RunData + Parser + CookieParser. | G23: POC validated this works. Production version needs full context fields.
A24: 26 | B24: Turbine | C24: turbine.properties → new config structure | D24: Migrate turbine.properties entries to appropriate Turbine 7 config files. Some properties move to YAAFI configs. | G24: Reference POC config as baseline.
A25: 27 | B25: Turbine | C25: Daemon and scheduler migration | D25: Verify DaemonFactory, GTPSchedulerService, and all daemon configurations work with Turbine 7 lifecycle. | G25: Daemons are critical for batch processing — FileToGTPInterfaceDaemon, CEWBulkProcessingDaemon etc.
A26: Turbine Subtotal | E26: =SUM(E18:E25) -> 0
A27: 4. Torque 3.1.1 → Torque 5.1+ (ORM / Data Layer) [PPT: Slide 4]
A28: 30 | B28: Torque | C28: Criteria.add() → Criteria.where() migration | D28: Update every ORM query using Criteria.add() to use Criteria.where(). Same logic, same SQL output, method renamed. | G28: Mechanical find-and-update. Volume to be confirmed from codebase scan.
A29: 31 | B29: Torque | C29: Village library removal (9 files) | D29: Rewrite 9 files that directly import com.workingdogs.village (Record, Value). Replace with Torque 5 native API or direct ResultSet. | G29: 9 files identified. Each needs individual analysis and rewrite.
A30: 32 | B30: Torque | C30: Peer class regeneration from schema.xml | D30: Regenerate all Torque Peer classes using Torque 5.1 generator against schema.xml. | G30: Requires schema.xml — location under verification (Gokul searching).
A31: 33 | B31: Torque | C31: Torque bootstrap via YAAFI | D31: Replace GTPComponentService (removed in Turbine 7) with YAAFI-based Torque initialisation. | G31: Configuration change — reference POC YAAFI setup.
A32: 34 | B32: Torque | C32: Torque 5.1 ORM validation on core tables | D32: Execute actual Criteria queries on GTPCompany, User, Role, Permission, Transaction tables. Verify CRUD operations. | G32: Core authorization tables — must validate before any module testing.
A33: 35 | B33: Torque | C33: Manager/cache layer validation | D33: Verify AbstractBaseManager and caching layer works with Torque 5.x. Permission caching critical for performance. | G33: Under verification — Torque 5 redesigned manager layer.
A34: Torque Subtotal | E34: =SUM(E28:E33) -> 0
A35: 5. Spring 4.2.9 → Spring 6.x + WSService (REST Layer) [PPT: Slide 5]
A36: 40 | B36: Spring | C36: CustomControllerArgumentResolver rewrite | D36: Rewrite the class that bridges Spring MVC and Turbine. Interface changes from javax.servlet to jakarta.servlet. Every controller depends on this. | G36: Strategic fix point. Single class but high impact — must be done first.
A37: 41 | B37: Spring | C37: Spring controller javax→jakarta migration | D37: Update all javax.servlet imports in Spring controllers to jakarta.servlet. Update ContextUtils.createRundata() calls. | G37: Per-controller work. Volume depends on controller count.
A38: 42 | B38: Spring | C38: Springfox → springdoc-openapi replacement | D38: Replace all Springfox annotations: @Api→@Tag, @ApiOperation→@Operation, @ApiParam→@Parameter. Configure springdoc. | G38: Mechanical annotation changes. No business logic impact.
A39: 43 | B39: Spring | C39: Spring Security 6 reconfiguration | D39: Rewrite FilterChainProxy configuration. Spring Security 6 filter chain API is completely different from 4.x. | G39: Security-critical — must be tested thoroughly.
A40: 44 | B40: Spring | C40: webservice-servlet.xml update | D40: Update Spring dispatcher config for Spring 6 namespace, bean definitions, argument resolvers, validation config. | G40: Single config file — but central to all WSService routing.
A41: 45 | B41: Spring | C41: javax.validation → jakarta.validation | D41: Update validation annotations and custom validators used in Spring controllers for GTP_PARAM_DATA interaction. | G41: May overlap with Java/Jakarta task — avoid double counting.
...

Sheet Layer 2
A1: Layer 2 — Module-Level Migration & Functional Validation (Development Mandays)
A2: Each business module requires developer-level migration validation — not just compilation, but end-to-end functional flow
A3: THIS IS WHERE 2 YEARS OF GEB PRODUCTION KNOWLEDGE IS REQUIRED — module flows, country variations, daemon behaviour, external integrations
A5: S.No | B5: Module | C5: Task | D5: Description / Scope | E5: Mandays (Dev) | F5: Owner | G5: Assumptions / Dependencies
A6: 1. Fund Transfer (TT / CBPR+)
B7: Complexity: Complex — multi-step approval, bulk processing, CEW→DMP→GEB flow, status callbacks, 6-country variations
A8: 1.1 | B8: Fund Transfer | C8: Portlet-specific code migration (screens, actions)
A9: 1.2 | B9: Fund Transfer | C9: Bulk file upload flow validation (IDB→CEW→DMP→GEB→CEW callback)
A10: 1.3 | B10: Fund Transfer | C10: CEWBulkProcessingDaemon validation
A11: 1.4 | B11: Fund Transfer | C11: DMP interface validation (SE_HFile processing)
A12: 1.5 | B12: Fund Transfer | C12: Status callback to CEW validation
A13: 1.6 | B13: Fund Transfer | C13: Country-specific TT configuration (SG, MY, VN, CN, HK, TH)
A14: 1.7 | B14: Fund Transfer | C14: ROS/Core Banking ACK callback validation
A15: Fund Transfer Subtotal | E15: =SUM(E8:E14) -> 0
A17: 2. Fund Transfer (BAU / Payroll)
B18: Complexity: Complex — different daemon, no CEW interaction, DMP S-File flow
A19: 2.1 | B19: Fund Transfer | C19: Portlet-specific code migration
A20: 2.2 | B20: Fund Transfer | C20: FileToGTPInterfaceDaemon validation
A21: 2.3 | B21: Fund Transfer | C21: BAU flow: IDB→GEB→DMP(S-File)→GEB(SE_HFile) validation
A22: 2.4 | B22: Fund Transfer | C22: prod_status_code handling validation
A23: 2.5 | B23: Fund Transfer | C23: Country-specific BAU configuration
A24: Fund Transfer Subtotal | E24: =SUM(E19:E23) -> 0
A26: 3. Account Statement
B27: Complexity: Complex — batch processing, core banking integration, Torque-heavy
A28: 3.1 | B28: Account Statement | C28: Portlet-specific code migration
A29: 3.2 | B29: Account Statement | C29: Account Statement batch daemon validation
A30: 3.3 | B30: Account Statement | C30: Core banking data import/export validation
A31: 3.4 | B31: Account Statement | C31: Torque-based object lifecycle (header→lines→transactions)
A32: 3.5 | B32: Account Statement | C32: Unicode/encoding handling (0x1A character issue previously found)
A33: 3.6 | B33: Account Statement | C33: Country-specific statement formats
A34: Account Statement Subtotal | E34: =SUM(E28:E33) -> 0
A36: 4. Letter of Credit (LC)
B37: Complexity: Complex — trade finance, EAI integration, multi-country
A38: 4.1 | B38: Letter of Credit | C38: Portlet-specific code migration
A39: 4.2 | B39: Letter of Credit | C39: LC creation/amendment/advising flow validation
A40: 4.3 | B40: Letter of Credit | C40: EAI integration validation
A41: 4.4 | B41: Letter of Credit | C41: Country-specific LC configuration
A42: 4.5 | B42: Letter of Credit | C42: XSL template rendering validation
A43: Letter of Credit Subtotal | E43: =SUM(E38:E42) -> 0
A45: 5. Bank Guarantee (BG)
...

Sheet Layer 3
A1: Layer 3 — Integration, Multi-Country & Build Validation (Development Mandays)
A3: S.No | B3: Component | C3: Task | D3: Description | E3: Mandays (Dev) | F3: Owner | G3: Assumptions / Notes
A4: 1 | B4: Integration | C4: Cross-module flow validation | D4: Validate flows that span multiple modules — e.g., Bulk File Upload touches FT, DMP, CEW, and IDB | G4: Requires all individual modules to be migrated first
A5: 2 | B5: Integration | C5: EAI connectivity validation | D5: Verify GEB→EAI integration works on new stack. Message formats, connection parameters, error handling. | G5: EAI system unchanged — GEB side needs validation
A6: 3 | B6: Integration | C6: DMP interface validation | D6: Verify all DMP↔GEB interfaces — S-File, SE_HFile, prod_status_code handling, rejection flows. | G6: Critical — known production issues in this interface
A7: 4 | B7: Integration | C7: IDB↔WSService endpoint validation | D7: Verify all IDB→GEB REST API calls work end-to-end on new stack. | G7: Depends on Spring 6 migration completion
A8: 5 | B8: Integration | C8: ROS/Core Banking callback validation | D8: Verify ACK processing from ROS, status code reconciliation, BK vs FT level status. | G8: Known fragile area — BK rejection vs FT status mismatch
A9: 6 | B9: Multi-Country | C9: Singapore (SG) configuration validation | D9: Validate SG-specific configs, templates, parameters, country-specific flows. | G9: Primary country — validate first
A10: 7 | B10: Multi-Country | C10: Malaysia (MY) configuration validation | D10: Validate MY-specific configs, encoding, templates, regulatory requirements.
A11: 8 | B11: Multi-Country | C11: Vietnam (VN) configuration validation | D11: Validate VN-specific configs, encoding (UTF-8 handling critical), templates. | G11: Encoding issues previously identified
A12: 9 | B12: Multi-Country | C12: China (CN) configuration validation | D12: Validate CN-specific configs, encoding, templates.
A13: 10 | B13: Multi-Country | C13: Hong Kong (HK) configuration validation | D13: Validate HK-specific configs, templates.
A14: 11 | B14: Multi-Country | C14: Thailand (TH) configuration validation | D14: Validate TH-specific configs, encoding, templates.
A15: 12 | B15: Build | C15: Full build packaging (WAR/EAR) | D15: Complete Maven build producing deployable WAR/EAR for EAP 8. All dependencies resolved. | G15: Final packaging after all components migrated
A16: 13 | B16: Build | C16: Deployment to SIT environment | D16: Deploy migrated GEB to SIT environment on EAP 8 + JDK 17. Resolve deployment issues. | G16: SIT environment must be provisioned with target stack
A17: 14 | B17: Build | C17: Daemon startup and scheduling validation | D17: Verify all GEB daemons start correctly, scheduling works, no race conditions. | G17: FileToGTPInterfaceDaemon, CEWBulkProcessingDaemon, Account Statement daemon etc.
A18: 15 | B18: Build | C18: Static resource and MIME type validation | D18: Verify all file types (.xsl, .psml, .vm, .properties, etc.) served correctly on EAP 8. | G18: MIME mappings and static resource servlet config may differ
A19: 16 | B19: Build | C19: Smoke test — critical path validation | D19: Execute critical business paths end-to-end: Login → FT creation → Approval → Release → Statement. | G19: Final developer validation before handoff for formal testing
A20: LAYER 3 — INTEGRATION & BUILD TOTAL | E20: =SUM(E4:E19) -> 0

Sheet Assumptions & Risks
A1: Assumptions, Dependencies & Risks
A3: # | B3: Type | C3: Description | D3: Mitigation / Notes
A4: 1 | B4: Assumption | C4: Scope: Estimation covers development effort until Build. Unit testing, SIT, UAT, buffer, and project management are handled separately by senior management.
A5: 2 | B5: Assumption | C5: Environment: SIT environment with JBoss EAP 8 + JDK 17 will be available for migration validation.
A6: 3 | B6: Assumption | C6: Source Access: Full GEB source code access is available. Finastra internal JAR source will be obtained through vendor engagement.
A7: 4 | B7: Assumption | C7: POC Baseline: Mini-GEB POC on Turbine 7 / Java 17 / Tomcat 10 serves as the validated baseline for platform migration approach.
A8: 5 | B8: Assumption | C8: schema.xml: Torque schema.xml file will be located or reverse-engineered from existing Peer classes and database DDL.
A9: 6 | B9: Assumption | C9: No Functional Change: Migration is a platform upgrade only — no business logic changes, no new features, no functional enhancements.
A10: 7 | B10: Assumption | C10: JAR Classification: Final JAR migration effort depends on classification outcome. Significant portion expected to be Java SE javax (safe).
A11: 8 | B11: Dependency | C11: I-Sprint: Jakarta EE compatible I-Sprint JAR required from vendor. Timeline not in Wipro control. POTENTIAL PROGRAMME BLOCKER.
A12: 9 | B12: Dependency | C12: Finastra: Java 17 compatible binaries or source code required from Finastra for internal JARs.
A13: 10 | B13: Dependency | C13: Bank: Confirmation needed: expected DMP behaviour when prod_status_code = 01. ROS ACK contract clarification.
A14: 11 | B14: Risk | C14: I-Sprint Blocker: If I-Sprint cannot deliver Jakarta EE JAR in time, token authentication will not function on upgraded stack.
A15: 12 | B15: Risk | C15: Finastra Source: If Finastra source is unavailable, internal JARs cannot be recompiled. Requires alternative approach or vendor escalation.
... A18: 15 | B18: Risk | C18: Country Variations: Country-specific configurations (especially encoding for VN, CN, TH) may surface issues only during multi-country testing.
